Workbook
Name Slicer_Discount_Category: #N/A
Name Slicer_Price_Category: #N/A
Name Slicer_Rating_Category: #N/A

Sheet Raw_Data
A1: Product | B1: Current price | C1: old price | D1: Discount | E1: Review | F1: Ratingd
A2: 115 Piece Set Of Multifunctional Precision Screwdrivers | B2: KSh 950 | C2: KSh 1,525 | D2: 0.38 | E2: -2 | F2: 4.5 out of 5
A3: Metal Decorative Hooks Key Hangers Entryway Wall Hooks Towel Hooks - Home | B3: KSh 527 | C3: KSh 999 | D3: 0.47 | E3: -14 | F3: 4.1 out of 5
A4: Portable Mini Cordless Car Vacuum Cleaner - Blue | B4: KSh 2,199 | C4: KSh 2,923 | D4: 0.25 | E4: -24 | F4: 4.6 out of 5
A5: Weighing Scale Digital Bathroom Body Fat Scale USB-Black | B5: KSh 1,580 | C5: KSh 2,499 | D5: 0.37 | E5: -7 | F5: 4.7 out of 5
A6: Portable Home Small Air Humidifier 3-Speed Fan - Green | B6: KSh 1,740 | C6: KSh 2,356 | D6: 0.26 | E6: -5 | F6: 4.8 out of 5
A7: 220V 60W Electric Soldering Iron Kits With Tools, Tips, And Multimeter | B7: KSh 2,999 | C7: KSh 3,290 | D7: 0.09 | E7: -15 | F7: 4 out of 5
A8: 137 Pieces Cake Decorating Tool Set Baking Supplies | B8: KSh 2,319 | C8: KSh 3,032 | D8: 0.24 | E8: -55 | F8: 4.6 out of 5
A9: Desk Foldable Fan Adjustable Fan Strong Wind 3 Gear Usb | B9: KSh 988 | C9: KSh 1,580 | D9: 0.37 | E9: -2 | F9: 4 out of 5
A10: LASA FOLDING TABLE SERVING STAND | B10: KSh 1,274 | C10: KSh 2,800 | D10: 0.55 | E10: -5 | F10: 4.8 out of 5
A11: 13 In 1 Home Repair Tools Box Kit Set | B11: KSh 1,600 | C11: KSh 2,929 | D11: 0.45 | E11: -5 | F11: 3.8 out of 5
A12: Genebre 115 In 1 Screwdriver Repairing Tool Set For IPhone Cellphone Hand Tool | B12: KSh 799 | C12: KSh 999 | D12: 0.2 | E12: -12 | F12: 4.1 out of 5
A13: 100 Pcs Crochet Hook Tool Set Knitting Hook Set With Box | B13: KSh 990 | C13: KSh 1,500 | D13: 0.34 | E13: -39 | F13: 4.7 out of 5
... A22: 3PCS Single Head Knitting Crochet Sweater Needle Set | B22: KSh 38 | C22: KSh 80 | D22: 0.53 | E22: -13 | F22: 3.3 out of 5
A23: 4pcs Bathroom/Kitchen Towel Rack,Roll Paper Holder,Towel Bars,Hook | B23: KSh 1,860 | C23: KSh 3,220 | D23: 0.42
A24: LED Romantic Spaceship Starry Sky Projector,Children's Bedroom Night Light-Blue | B24: KSh 880 | C24: KSh 1,350 | D24: 0.35 | E24: -6 | F24: 4 out of 5
A25: Foldable Overbed Table/Desk | B25: KSh 1,650 | C25: KSh 2,150 | D25: 0.23 | E25: -14 | F25: 4.4 out of 5
A26: LASA 3 Tier Bamboo Shoe Bench Storage Shelf | B26: KSh 2,048 | C26: KSh 4,500 | D26: 0.54 | E26: -7 | F26: 4.3 out of 5
A27: Electronic Digital Display Vernier Caliper | B27: KSh 420 | C27: KSh 647 | D27: 0.35 | E27: -49 | F27: 4.6 out of 5
A28: Portable Wardrobe Nonwoven With 3 Hanging Rods And 6 Storage Shelves | B28: KSh 2,880 | C28: KSh 3,520 | D28: 0.18 | E28: -12 | F28: 3.8 out of 5
A29: 12 Litre Black Insulated Lunch Box | B29: KSh 1,350 | C29: KSh 1,990 | D29: 0.32 | E29: -13 | F29: 3.8 out of 5
A30: 52 Pieces Cake Decorating Tool Set Gift Kit Baking Supplies | B30: KSh 1,758 | C30: KSh 2,499 | D30: 0.3 | E30: -20 | F30: 4.1 out of 5
A31: MultiFunctional Storage Rack Multi-layer Bookshelf | B31: KSh 2,200 | C31: KSh 4,080 | D31: 0.46
A32: Exfoliate And Exfoliate Face Towel - Black | B32: KSh 185 | C32: KSh 382 | D32: 0.52 | E32: -9 | F32: 4.3 out of 5
A33: 12 Litre Insulated Lunch Box Grey | B33: KSh 980 | C33: KSh 1,490 | D33: 0.34 | E33: -12 | F33: 4.7 out of 5
A34: LED Eye Protection Desk Lamp , Study, Reading, USB Fan - Double Pen Holder | B34: KSh 1,820 | C34: KSh 3,490 | D34: 0.48 | E34: -9 | F34: 4.3 out of 5
A35: 53Pcs/Set Yarn Knitting Crochet Hooks With Bag - Fortune Cat | B35: KSh 1,940 | C35: KSh 2,650 | D35: 0.27 | E35: -20 | F35: 4.7 out of 5
A36: 53 Pieces/Set Yarn Knitting Crochet Hooks With Bag - Pansies | B36: KSh 1,980 | C36: KSh 2,699 | D36: 0.27 | E36: -32 | F36: 4.5 out of 5
A37: DIY File Folder, Office Drawer File Holder, Pen Holder, Desktop Storage Rack | B37: KSh 1,620 | C37: KSh 2,690 | D37: 0.4 | E37: -1 | F37: 5 out of 5
A38: Classic Black Cat Cotton Hemp Pillow Case For Home Car | B38: KSh 171 | C38: KSh 360 | D38: 0.53 | E38: -2 | F38: 5 out of 5
A39: Punch-free Great Load Bearing Bathroom Storage Rack Wall Shelf-White | B39: KSh 389 | C39: KSh 656 | D39: 0.41 | E39: -36 | F39: 4.3 out of 5
A40: 1/2/3 Seater Elastic Sofa Cover,Living Room/Home Decor Chair Cover-Grey | B40: KSh 1,620 - KSh 1,980 | C40: KSh 2,200 - KSh 3,200 | D40: 0.38 | E40: -2 | F40: 4.5 out of 5
A41: LASA Stainless Steel Double Wall Mount Soap Dispenser - 500ml | B41: KSh 2,750 | C41: KSh 4,471 | D41: 0.38
A42: 4M Float Switch Water Level Controller -Water Tank | B42: KSh 475 | C42: KSh 931 | D42: 0.49
A43: Modern Sofa Throw Pillow Cover-45x45cm-Blue&Red | B43: KSh 238 | C43: KSh 476 | D43: 0.5
A44: Balloon Insert, Birthday Party Balloon Set, PU Leather | B44: KSh 610 | C44: KSh 1,060 | D44: 0.42
A45: Balloon Insert, Birthday Party Balloon Set, PU Leather | B45: KSh 610 | C45: KSh 1,060 | D45: 0.42
A46: Shower Cap Wide Elastic Band Cover Reusable Bashroom Cap | B46: KSh 2,132 | C46: KSh 2,169 | D46: 0.02
A47: Christmas Elk Fence Yard Lawn Decorations Cute For Holidays | B47: KSh 999 | C47: KSh 2,000 | D47: 0.5
A48: 60W Hot Melt Glue Sprayer - Efficient And Stable Glue Dispensing | B48: KSh 1,190 | C48: KSh 1,785 | D48: 0.33
...

Sheet Cleaned_Data
A1: Product | B1: Current Price | C1: Old Price | D1: Price Category | E1: Discount Amount | F1: Discount | G1: Discount Category | H1: Review | I1: Rating | J1: Rating Category
A2: 6 In 1 Bottle Can Opener Multifunctional Easy Opener | B2: 199 | C2: 553 | D2: =IF(Excel_jumia_dataset3[[#This Row],[Current Price]]="","Missing",IF(Excel_jumia_dataset3[[#This Row],[Current Price]]<Data_Analysis!$B$21,"Low Price",IF(Excel_jumia_dataset3[[#This Row],[Current Price]]<Data_Analysis!$B$22,"Medium Price","High Price"))) -> Low Price | E2: =Excel_jumia_dataset3[[#This Row],[Old Price]]-Excel_jumia_dataset3[[#This Row],[Current Price]] -> 354 | F2: 0.64 | G2: =IF(F2<20%,"Low Discount",IF(F2<=40%,"Medium Discount", "High Discount")) -> High Discount | J2: Not Provided
A3: Creative Owl Shape Keychain Black | B3: 199 | C3: 504 | D3: =IF(Excel_jumia_dataset3[[#This Row],[Current Price]]="","Missing",IF(Excel_jumia_dataset3[[#This Row],[Current Price]]<Data_Analysis!$B$21,"Low Price",IF(Excel_jumia_dataset3[[#This Row],[Current Price]]<Data_Analysis!$B$22,"Medium Price","High Price"))) -> Low Price | E3: =Excel_jumia_dataset3[[#This Row],[Old Price]]-Excel_jumia_dataset3[[#This Row],[Current Price]] -> 305 | F3: 0.61 | G3: =IF(F3<20%,"Low Discount",IF(F3<=40%,"Medium Discount", "High Discount")) -> High Discount | J3: Not Provided
A4: Simple Metal Dog Art Sculpture Decoration For Home Office | B4: 399 | C4: 896 | D4: =IF(Excel_jumia_dataset3[[#This Row],[Current Price]]="","Missing",IF(Excel_jumia_dataset3[[#This Row],[Current Price]]<Data_Analysis!$B$21,"Low Price",IF(Excel_jumia_dataset3[[#This Row],[Current Price]]<Data_Analysis!$B$22,"Medium Price","High Price"))) -> Low Price | E4: =Excel_jumia_dataset3[[#This Row],[Old Price]]-Excel_jumia_dataset3[[#This Row],[Current Price]] -> 497 | F4: 0.55 | G4: =IF(F4<20%,"Low Discount",IF(F4<=40%,"Medium Discount", "High Discount")) -> High Discount | J4: Not Provided
A5: 2PCS Ice Silk Square Cushion Cover Pillowcases - 65x65cm | B5: 1200 | C5: 2400 | D5: =IF(Excel_jumia_dataset3[[#This Row],[Current Price]]="","Missing",IF(Excel_jumia_dataset3[[#This Row],[Current Price]]<Data_Analysis!$B$21,"Low Price",IF(Excel_jumia_dataset3[[#This Row],[Current Price]]<Data_Analysis!$B$22,"Medium Price","High Price"))) -> Medium Price | E5: =Excel_jumia_dataset3[[#This Row],[Old Price]]-Excel_jumia_dataset3[[#This Row],[Current Price]] -> 1200 | F5: 0.5 | G5: =IF(F5<20%,"Low Discount",IF(F5<=40%,"Medium Discount", "High Discount")) -> High Discount | J5: Not Provided
A6: Christmas Elk Fence Yard Lawn Decorations Cute For Holidays | B6: 999 | C6: 2000 | D6: =IF(Excel_jumia_dataset3[[#This Row],[Current Price]]="","Missing",IF(Excel_jumia_dataset3[[#This Row],[Current Price]]<Data_Analysis!$B$21,"Low Price",IF(Excel_jumia_dataset3[[#This Row],[Current Price]]<Data_Analysis!$B$22,"Medium Price","High Price"))) -> Medium Price | E6: =Excel_jumia_dataset3[[#This Row],[Old Price]]-Excel_jumia_dataset3[[#This Row],[Current Price]] -> 1001 | F6: 0.5 | G6: =IF(F6<20%,"Low Discount",IF(F6<=40%,"Medium Discount", "High Discount")) -> High Discount | J6: Not Provided
A7: Wall Clock With Hidden Safe Box | B7: 850 | C7: 1700 | D7: =IF(Excel_jumia_dataset3[[#This Row],[Current Price]]="","Missing",IF(Excel_jumia_dataset3[[#This Row],[Current Price]]<Data_Analysis!$B$21,"Low Price",IF(Excel_jumia_dataset3[[#This Row],[Current Price]]<Data_Analysis!$B$22,"Medium Price","High Price"))) -> Medium Price | E7: =Excel_jumia_dataset3[[#This Row],[Old Price]]-Excel_jumia_dataset3[[#This Row],[Current Price]] -> 850 | F7: 0.5 | G7: =IF(F7<20%,"Low Discount",IF(F7<=40%,"Medium Discount", "High Discount")) -> High Discount | J7: Not Provided
A8: Brush & Paintbrush Cleaning Tool Pink | B8: 299 | C8: 600 | D8: =IF(Excel_jumia_dataset3[[#This Row],[Current Price]]="","Missing",IF(Excel_jumia_dataset3[[#This Row],[Current Price]]<Data_Analysis!$B$21,"Low Price",IF(Excel_jumia_dataset3[[#This Row],[Current Price]]<Data_Analysis!$B$22,"Medium Price","High Price"))) -> Low Price | E8: =Excel_jumia_dataset3[[#This Row],[Old Price]]-Excel_jumia_dataset3[[#This Row],[Current Price]] -> 301 | F8: 0.5 | G8: =IF(F8<20%,"Low Discount",IF(F8<=40%,"Medium Discount", "High Discount")) -> High Discount | J8: Not Provided
A9: Modern Sofa Throw Pillow Cover-45x45cm-Blue&Red | B9: 238 | C9: 476 | D9: =IF(Excel_jumia_dataset3[[#This Row],[Current Price]]="","Missing",IF(Excel_jumia_dataset3[[#This Row],[Current Price]]<Data_Analysis!$B$21,"Low Price",IF(Excel_jumia_dataset3[[#This Row],[Current Price]]<Data_Analysis!$B$22,"Medium Price","High Price"))) -> Low Price | E9: =Excel_jumia_dataset3[[#This Row],[Old Price]]-Excel_jumia_dataset3[[#This Row],[Current Price]] -> 238 | F9: 0.5 | G9: =IF(F9<20%,"Low Discount",IF(F9<=40%,"Medium Discount", "High Discount")) -> High Discount | J9: Not Provided
A10: Angle Measuring Tool Full Metal Multi Angle Measuring Tool | B10: 799 | C10: 1567 | D10: =IF(Excel_jumia_dataset3[[#This Row],[Current Price]]="","Missing",IF(Excel_jumia_dataset3[[#This Row],[Current Price]]<Data_Analysis!$B$21,"Low Price",IF(Excel_jumia_dataset3[[#This Row],[Current Price]]<Data_Analysis!$B$22,"Medium Price","High Price"))) -> Medium Price | E10: =Excel_jumia_dataset3[[#This Row],[Old Price]]-Excel_jumia_dataset3[[#This Row],[Current Price]] -> 768 | F10: 0.49 | G10: =IF(F10<20%,"Low Discount",IF(F10<=40%,"Medium Discount", "High Discount")) -> High Discount | J10: Not Provided
A11: Car Phone Charging Stand | B11: 671 | C11: 1316 | D11: =IF(Excel_jumia_dataset3[[#This Row],[Current Price]]="","Missing",IF(Excel_jumia_dataset3[[#This Row],[Current Price]]<Data_Analysis!$B$21,"Low Price",IF(Excel_jumia_dataset3[[#This Row],[Current Price]]<Data_Analysis!$B$22,"Medium Price","High Price"))) -> Medium Price | E11: =Excel_jumia_dataset3[[#This Row],[Old Price]]-Excel_jumia_dataset3[[#This Row],[Current Price]] -> 645 | F11: 0.49 | G11: =IF(F11<20%,"Low Discount",IF(F11<=40%,"Medium Discount", "High Discount")) -> High Discount | J11: Not Provided
A12: Angle Measuring Tool Full Metal Multi Angle Measuring Tool | B12: 657 | C12: 1288 | D12: =IF(Excel_jumia_dataset3[[#This Row],[Current Price]]="","Missing",IF(Excel_jumia_dataset3[[#This Row],[Current Price]]<Data_Analysis!$B$21,"Low Price",IF(Excel_jumia_dataset3[[#This Row],[Current Price]]<Data_Analysis!$B$22,"Medium Price","High Price"))) -> Medium Price | E12: =Excel_jumia_dataset3[[#This Row],[Old Price]]-Excel_jumia_dataset3[[#This Row],[Current Price]] -> 631 | F12: 0.49 | G12: =IF(F12<20%,"Low Discount",IF(F12<=40%,"Medium Discount", "High Discount")) -> High Discount | J12: Not Provided
A13: 220V 60W Electric Soldering Iron Kits With Tools, Tips, And Multimeter | B13: 2999 | C13: 3290 | D13: =IF(Excel_jumia_dataset3[[#This Row],[Current Price]]="","Missing",IF(Excel_jumia_dataset3[[#This Row],[Current Price]]<Data_Analysis!$B$21,"Low Price",IF(Excel_jumia_dataset3[[#This Row],[Current Price]]<Data_Analysis!$B$22,"Medium Price","High Price"))) -> High Price | E13: =Excel_jumia_dataset3[[#This Row],[Old Price]]-Excel_jumia_dataset3[[#This Row],[Current Price]] -> 291 | F13: 0.09 | G13: =IF(F13<20%,"Low Discount",IF(F13<=40%,"Medium Discount", "High Discount")) -> Low Discount | H13: 15 | I13: 4 | J13: =IF(ISBLANK(I13),"",IF(I13<3,"Poor",IF(I13>=4.5,"Excellent","Average"))) -> Average
A14: Baby Early Education Shape And Color Cognitive Training Toys | B14: 525 | C14: 1029 | D14: =IF(Excel_jumia_dataset3[[#This Row],[Current Price]]="","Missing",IF(Excel_jumia_dataset3[[#This Row],[Current Price]]<Data_Analysis!$B$21,"Low Price",IF(Excel_jumia_dataset3[[#This Row],[Current Price]]<Data_Analysis!$B$22,"Medium Price","High Price"))) -> Medium Price | E14: =Excel_jumia_dataset3[[#This Row],[Old Price]]-Excel_jumia_dataset3[[#This Row],[Current Price]] -> 504 | F14: 0.49 | G14: =IF(F14<20%,"Low Discount",IF(F14<=40%,"Medium Discount", "High Discount")) -> High Discount | J14: Not Provided
A15: 5 Pieces/set Of Stainless Steel Induction Cooker Pots | B15: 2170 | C15: 2500 | D15: =IF(Excel_jumia_dataset3[[#This Row],[Current Price]]="","Missing",IF(Excel_jumia_dataset3[[#This Row],[Current Price]]<Data_Analysis!$B$21,"Low Price",IF(Excel_jumia_dataset3[[#This Row],[Current Price]]<Data_Analysis!$B$22,"Medium Price","High Price"))) -> High Price | E15: =Excel_jumia_dataset3[[#This Row],[Old Price]]-Excel_jumia_dataset3[[#This Row],[Current Price]] -> 330 | F15: 0.13 | G15: =IF(F15<20%,"Low Discount",IF(F15<=40%,"Medium Discount", "High Discount")) -> Low Discount | H15: 6 | I15: 2.5 | J15: =IF(ISBLANK(I15),"",IF(I15<3,"Poor",IF(I15>=4.5,"Excellent","Average"))) -> Poor
A16: 4M Float Switch Water Level Controller -Water Tank | B16: 475 | C16: 931 | D16: =IF(Excel_jumia_dataset3[[#This Row],[Current Price]]="","Missing",IF(Excel_jumia_dataset3[[#This Row],[Current Price]]<Data_Analysis!$B$21,"Low Price",IF(Excel_jumia_dataset3[[#This Row],[Current Price]]<Data_Analysis!$B$22,"Medium Price","High Price"))) -> Low Price | E16: =Excel_jumia_dataset3[[#This Row],[Old Price]]-Excel_jumia_dataset3[[#This Row],[Current Price]] -> 456 | F16: 0.49 | G16: =IF(F16<20%,"Low Discount",IF(F16<=40%,"Medium Discount", "High Discount")) -> High Discount | J16: Not Provided
A17: Cartoon Car Decoration Cute Individuality For Car Home Desk | B17: 274 | C17: 537 | D17: =IF(Excel_jumia_dataset3[[#This Row],[Current Price]]="","Missing",IF(Excel_jumia_dataset3[[#This Row],[Current Price]]<Data_Analysis!$B$21,"Low Price",IF(Excel_jumia_dataset3[[#This Row],[Current Price]]<Data_Analysis!$B$22,"Medium Price","High Price"))) -> Low Price | E17: =Excel_jumia_dataset3[[#This Row],[Old Price]]-Excel_jumia_dataset3[[#This Row],[Current Price]] -> 263 | F17: 0.49 | G17: =IF(F17<20%,"Low Discount",IF(F17<=40%,"Medium Discount", "High Discount")) -> High Discount | J17: Not Provided
A18: Portable Wardrobe Nonwoven With 3 Hanging Rods And 6 Storage Shelves | B18: 2880 | C18: 3520 | D18: =IF(Excel_jumia_dataset3[[#This Row],[Current Price]]="","Missing",IF(Excel_jumia_dataset3[[#This Row],[Current Price]]<Data_Analysis!$B$21,"Low Price",IF(Excel_jumia_dataset3[[#This Row],[Current Price]]<Data_Analysis!$B$22,"Medium Price","High Price"))) -> High Price | E18: =Excel_jumia_dataset3[[#This Row],[Old Price]]-Excel_jumia_dataset3[[#This Row],[Current Price]] -> 640 | F18: 0.18 | G18: =IF(F18<20%,"Low Discount",IF(F18<=40%,"Medium Discount", "High Discount")) -> Low Discount | H18: 12 | I18: 3.8 | J18: =IF(ISBLANK(I18),"",IF(I18<3,"Poor",IF(I18>=4.5,"Excellent","Average"))) -> Average
A19: LED Wall Digital Alarm Clock Study Home 12 / 24H Clock Calendar | B19: 2999 | C19: 3699 | D19: =IF(Excel_jumia_dataset3[[#This Row],[Current Price]]="","Missing",IF(Excel_jumia_dataset3[[#This Row],[Current Price]]<Data_Analysis!$B$21,"Low Price",IF(Excel_jumia_dataset3[[#This Row],[Current Price]]<Data_Analysis!$B$22,"Medium Price","High Price"))) -> High Price | E19: =Excel_jumia_dataset3[[#This Row],[Old Price]]-Excel_jumia_dataset3[[#This Row],[Current Price]] -> 700 | F19: 0.19 | G19: =IF(F19<20%,"Low Discount",IF(F19<=40%,"Medium Discount", "High Discount")) -> Low Discount | H19: 5 | I19: 4.6 | J19: =IF(ISBLANK(I19),"",IF(I19<3,"Poor",IF(I19>=4.5,"Excellent","Average"))) -> Excellent
A20: Genebre 115 In 1 Screwdriver Repairing Tool Set For IPhone Cellphone Hand Tool | B20: 799 | C20: 999 | D20: =IF(Excel_jumia_dataset3[[#This Row],[Current Price]]="","Missing",IF(Excel_jumia_dataset3[[#This Row],[Current Price]]<Data_Analysis!$B$21,"Low Price",IF(Excel_jumia_dataset3[[#This Row],[Current Price]]<Data_Analysis!$B$22,"Medium Price","High Price"))) -> Medium Price | E20: =Excel_jumia_dataset3[[#This Row],[Old Price]]-Excel_jumia_dataset3[[#This Row],[Current Price]] -> 200 | F20: 0.2 | G20: =IF(F20<20%,"Low Discount",IF(F20<=40%,"Medium Discount", "High Discount")) -> Medium Discount | H20: 12 | I20: 4.1 | J20: =IF(ISBLANK(I20),"",IF(I20<3,"Poor",IF(I20>=4.5,"Excellent","Average"))) -> Average
A21: Konka Healty Electric Kettle, 24-hour Heat Preservation,1.5L,800W, White | B21: 3640 | C21: 4588 | D21: =IF(Excel_jumia_dataset3[[#This Row],[Current Price]]="","Missing",IF(Excel_jumia_dataset3[[#This Row],[Current Price]]<Data_Analysis!$B$21,"Low Price",IF(Excel_jumia_dataset3[[#This Row],[Current Price]]<Data_Analysis!$B$22,"Medium Price","High Price"))) -> High Price | E21: =Excel_jumia_dataset3[[#This Row],[Old Price]]-Excel_jumia_dataset3[[#This Row],[Current Price]] -> 948 | F21: 0.21 | G21: =IF(F21<20%,"Low Discount",IF(F21<=40%,"Medium Discount", "High Discount")) -> Medium Discount | H21: 1 | I21: 5 | J21: =IF(ISBLANK(I21),"",IF(I21<3,"Poor",IF(I21>=4.5,"Excellent","Average"))) -> Excellent
A22: VIC Wireless Vacuum Cleaner Dual Use For Home And Car 120W High Power Powerful | B22: 1220 | C22: 1555 | D22: =IF(Excel_jumia_dataset3[[#This Row],[Current Price]]="","Missing",IF(Excel_jumia_dataset3[[#This Row],[Current Price]]<Data_Analysis!$B$21,"Low Price",IF(Excel_jumia_dataset3[[#This Row],[Current Price]]<Data_Analysis!$B$22,"Medium Price","High Price"))) -> Medium Price | E22: =Excel_jumia_dataset3[[#This Row],[Old Price]]-Excel_jumia_dataset3[[#This Row],[Current Price]] -> 335 | F22: 0.22 | G22: =IF(F22<20%,"Low Discount",IF(F22<=40%,"Medium Discount", "High Discount")) -> Medium Discount | H22: 16 | I22: 2.9 | J22: =IF(ISBLANK(I22),"",IF(I22<3,"Poor",IF(I22>=4.5,"Excellent","Average"))) -> Poor
A23: 4 Piece Coloured Stainless Steel Kitchenware Set | B23: 248 | C23: 486 | D23: =IF(Excel_jumia_dataset3[[#This Row],[Current Price]]="","Missing",IF(Excel_jumia_dataset3[[#This Row],[Current Price]]<Data_Analysis!$B$21,"Low Price",IF(Excel_jumia_dataset3[[#This Row],[Current Price]]<Data_Analysis!$B$22,"Medium Price","High Price"))) -> Low Price | E23: =Excel_jumia_dataset3[[#This Row],[Old Price]]-Excel_jumia_dataset3[[#This Row],[Current Price]] -> 238 | F23: 0.49 | G23: =IF(F23<20%,"Low Discount",IF(F23<=40%,"Medium Discount", "High Discount")) -> High Discount | J23: Not Provided
A24: Foldable Overbed Table/Desk | B24: 1650 | C24: 2150 | D24: =IF(Excel_jumia_dataset3[[#This Row],[Current Price]]="","Missing",IF(Excel_jumia_dataset3[[#This Row],[Current Price]]<Data_Analysis!$B$21,"Low Price",IF(Excel_jumia_dataset3[[#This Row],[Current Price]]<Data_Analysis!$B$22,"Medium Price","High Price"))) -> Medium Price | E24: =Excel_jumia_dataset3[[#This Row],[Old Price]]-Excel_jumia_dataset3[[#This Row],[Current Price]] -> 500 | F24: 0.23 | G24: =IF(F24<20%,"Low Discount",IF(F24<=40%,"Medium Discount", "High Discount")) -> Medium Discount | H24: 14 | I24: 4.4 | J24: =IF(ISBLANK(I24),"",IF(I24<3,"Poor",IF(I24>=4.5,"Excellent","Average"))) -> Average
A25: 137 Pieces Cake Decorating Tool Set Baking Supplies | B25: 2319 | C25: 3032 | D25: =IF(Excel_jumia_dataset3[[#This Row],[Current Price]]="","Missing",IF(Excel_jumia_dataset3[[#This Row],[Current Price]]<Data_Analysis!$B$21,"Low Price",IF(Excel_jumia_dataset3[[#This Row],[Current Price]]<Data_Analysis!$B$22,"Medium Price","High Price"))) -> High Price | E25: =Excel_jumia_dataset3[[#This Row],[Old Price]]-Excel_jumia_dataset3[[#This Row],[Current Price]] -> 713 | F25: 0.24 | G25: =IF(F25<20%,"Low Discount",IF(F25<=40%,"Medium Discount", "High Discount")) -> Medium Discount | H25: 55 | I25: 4.6 | J25: =IF(ISBLANK(I25),"",IF(I25<3,"Poor",IF(I25>=4.5,"Excellent","Average"))) -> Excellent
A26: 7PCS Silicone Thumb Knife Finger Protector Vegetable Harvesting Knife | B26: 230 | C26: 450 | D26: =IF(Excel_jumia_dataset3[[#This Row],[Current Price]]="","Missing",IF(Excel_jumia_dataset3[[#This Row],[Current Price]]<Data_Analysis!$B$21,"Low Price",IF(Excel_jumia_dataset3[[#This Row],[Current Price]]<Data_Analysis!$B$22,"Medium Price","High Price"))) -> Low Price | E26: =Excel_jumia_dataset3[[#This Row],[Old Price]]-Excel_jumia_dataset3[[#This Row],[Current Price]] -> 220 | F26: 0.49 | G26: =IF(F26<20%,"Low Discount",IF(F26<=40%,"Medium Discount", "High Discount")) -> High Discount | J26: Not Provided
A27: Portable Mini Cordless Car Vacuum Cleaner - Blue | B27: 2199 | C27: 2923 | D27: =IF(Excel_jumia_dataset3[[#This Row],[Current Price]]="","Missing",IF(Excel_jumia_dataset3[[#This Row],[Current Price]]<Data_Analysis!$B$21,"Low Price",IF(Excel_jumia_dataset3[[#This Row],[Current Price]]<Data_Analysis!$B$22,"Medium Price","High Price"))) -> High Price | E27: =Excel_jumia_dataset3[[#This Row],[Old Price]]-Excel_jumia_dataset3[[#This Row],[Current Price]] -> 724 | F27: 0.25 | G27: =IF(F27<20%,"Low Discount",IF(F27<=40%,"Medium Discount", "High Discount")) -> Medium Discount | H27: 24 | I27: 4.6 | J27: =IF(ISBLANK(I27),"",IF(I27<3,"Poor",IF(I27>=4.5,"Excellent","Average"))) -> Excellent
A28: Portable Home Small Air Humidifier 3-Speed Fan - Green | B28: 1740 | C28: 2356 | D28: =IF(Excel_jumia_dataset3[[#This Row],[Current Price]]="","Missing",IF(Excel_jumia_dataset3[[#This Row],[Current Price]]<Data_Analysis!$B$21,"Low Price",IF(Excel_jumia_dataset3[[#This Row],[Current Price]]<Data_Analysis!$B$22,"Medium Price","High Price"))) -> High Price | E28: =Excel_jumia_dataset3[[#This Row],[Old Price]]-Excel_jumia_dataset3[[#This Row],[Current Price]] -> 616 | F28: 0.26 | G28: =IF(F28<20%,"Low Discount",IF(F28<=40%,"Medium Discount", "High Discount")) -> Medium Discount | H28: 5 | I28: 4.8 | J28: =IF(ISBLANK(I28),"",IF(I28<3,"Poor",IF(I28>=4.5,"Excellent","Average"))) -> Excellent
A29: Creative Owl Shape Keychain Black | B29: 176 | C29: 345 | D29: =IF(Excel_jumia_dataset3[[#This Row],[Current Price]]="","Missing",IF(Excel_jumia_dataset3[[#This Row],[Current Price]]<Data_Analysis!$B$21,"Low Price",IF(Excel_jumia_dataset3[[#This Row],[Current Price]]<Data_Analysis!$B$22,"Medium Price","High Price"))) -> Low Price | E29: =Excel_jumia_dataset3[[#This Row],[Old Price]]-Excel_jumia_dataset3[[#This Row],[Current Price]] -> 169 | F29: 0.49 | G29: =IF(F29<20%,"Low Discount",IF(F29<=40%,"Medium Discount", "High Discount")) -> High Discount | J29: Not Provided
A30: 53 Pieces/Set Yarn Knitting Crochet Hooks With Bag - Pansies | B30: 1980 | C30: 2699 | D30: =IF(Excel_jumia_dataset3[[#This Row],[Current Price]]="","Missing",IF(Excel_jumia_dataset3[[#This Row],[Current Price]]<Data_Analysis!$B$21,"Low Price",IF(Excel_jumia_dataset3[[#This Row],[Current Price]]<Data_Analysis!$B$22,"Medium Price","High Price"))) -> High Price | E30: =Excel_jumia_dataset3[[#This Row],[Old Price]]-Excel_jumia_dataset3[[#This Row],[Current Price]] -> 719 | F30: 0.27 | G30: =IF(F30<20%,"Low Discount",IF(F30<=40%,"Medium Discount", "High Discount")) -> Medium Discount | H30: 32 | I30: 4.5 | J30: =IF(ISBLANK(I30),"",IF(I30<3,"Poor",IF(I30>=4.5,"Excellent","Average"))) -> Excellent
A31: 53Pcs/Set Yarn Knitting Crochet Hooks With Bag - Fortune Cat | B31: 1940 | C31: 2650 | D31: =IF(Excel_jumia_dataset3[[#This Row],[Current Price]]="","Missing",IF(Excel_jumia_dataset3[[#This Row],[Current Price]]<Data_Analysis!$B$21,"Low Price",IF(Excel_jumia_dataset3[[#This Row],[Current Price]]<Data_Analysis!$B$22,"Medium Price","High Price"))) -> High Price | E31: =Excel_jumia_dataset3[[#This Row],[Old Price]]-Excel_jumia_dataset3[[#This Row],[Current Price]] -> 710 | F31: 0.27 | G31: =IF(F31<20%,"Low Discount",IF(F31<=40%,"Medium Discount", "High Discount")) -> Medium Discount | H31: 20 | I31: 4.7 | J31: =IF(ISBLANK(I31),"",IF(I31<3,"Poor",IF(I31>=4.5,"Excellent","Average"))) -> Excellent
A32: Large Lazy Inflatable Sofa Chairs PVC Lounger Seat Bag | B32: 2300 | C32: 3240 | D32: =IF(Excel_jumia_dataset3[[#This Row],[Current Price]]="","Missing",IF(Excel_jumia_dataset3[[#This Row],[Current Price]]<Data_Analysis!$B$21,"Low Price",IF(Excel_jumia_dataset3[[#This Row],[Current Price]]<Data_Analysis!$B$22,"Medium Price","High Price"))) -> High Price | E32: =Excel_jumia_dataset3[[#This Row],[Old Price]]-Excel_jumia_dataset3[[#This Row],[Current Price]] -> 940 | F32: 0.29 | G32: =IF(F32<20%,"Low Discount",IF(F32<=40%,"Medium Discount", "High Discount")) -> Medium Discount | H32: 5 | I32: 3 | J32: =IF(ISBLANK(I32),"",IF(I32<3,"Poor",IF(I32>=4.5,"Excellent","Average"))) -> Average
A33: 52 Pieces Cake Decorating Tool Set Gift Kit Baking Supplies | B33: 1758 | C33: 2499 | D33: =IF(Excel_jumia_dataset3[[#This Row],[Current Price]]="","Missing",IF(Excel_jumia_dataset3[[#This Row],[Current Price]]<Data_Analysis!$B$21,"Low Price",IF(Excel_jumia_dataset3[[#This Row],[Current Price]]<Data_Analysis!$B$22,"Medium Price","High Price"))) -> High Price | E33: =Excel_jumia_dataset3[[#This Row],[Old Price]]-Excel_jumia_dataset3[[#This Row],[Current Price]] -> 741 | F33: 0.3 | G33: =IF(F33<20%,"Low Discount",IF(F33<=40%,"Medium Discount", "High Discount")) -> Medium Discount | H33: 20 | I33: 4.1 | J33: =IF(ISBLANK(I33),"",IF(I33<3,"Poor",IF(I33>=4.5,"Excellent","Average"))) -> Average
A34: 12 Litre Black Insulated Lunch Box | B34: 1350 | C34: 1990 | D34: =IF(Excel_jumia_dataset3[[#This Row],[Current Price]]="","Missing",IF(Excel_jumia_dataset3[[#This Row],[Current Price]]<Data_Analysis!$B$21,"Low Price",IF(Excel_jumia_dataset3[[#This Row],[Current Price]]<Data_Analysis!$B$22,"Medium Price","High Price"))) -> Medium Price | E34: =Excel_jumia_dataset3[[#This Row],[Old Price]]-Excel_jumia_dataset3[[#This Row],[Current Price]] -> 640 | F34: 0.32 | G34: =IF(F34<20%,"Low Discount",IF(F34<=40%,"Medium Discount", "High Discount")) -> Medium Discount | H34: 13 | I34: 3.8 | J34: =IF(ISBLANK(I34),"",IF(I34<3,"Poor",IF(I34>=4.5,"Excellent","Average"))) -> Average
A35: Multifunction Laser Level With Adjustment Tripod | B35: 1680 | C35: 2499 | D35: =IF(Excel_jumia_dataset3[[#This Row],[Current Price]]="","Missing",IF(Excel_jumia_dataset3[[#This Row],[Current Price]]<Data_Analysis!$B$21,"Low Price",IF(Excel_jumia_dataset3[[#This Row],[Current Price]]<Data_Analysis!$B$22,"Medium Price","High Price"))) -> High Price | E35: =Excel_jumia_dataset3[[#This Row],[Old Price]]-Excel_jumia_dataset3[[#This Row],[Current Price]] -> 819 | F35: 0.33 | G35: =IF(F35<20%,"Low Discount",IF(F35<=40%,"Medium Discount", "High Discount")) -> Medium Discount | H35: 9 | I35: 4.2 | J35: =IF(ISBLANK(I35),"",IF(I35<3,"Poor",IF(I35>=4.5,"Excellent","Average"))) -> Average
A36: Portable Wine Table With Folding Round Table | B36: 1300 | C36: 2500 | D36: =IF(Excel_jumia_dataset3[[#This Row],[Current Price]]="","Missing",IF(Excel_jumia_dataset3[[#This Row],[Current Price]]<Data_Analysis!$B$21,"Low Price",IF(Excel_jumia_dataset3[[#This Row],[Current Price]]<Data_Analysis!$B$22,"Medium Price","High Price"))) -> Medium Price | E36: =Excel_jumia_dataset3[[#This Row],[Old Price]]-Excel_jumia_dataset3[[#This Row],[Current Price]] -> 1200 | F36: 0.48 | G36: =IF(F36<20%,"Low Discount",IF(F36<=40%,"Medium Discount", "High Discount")) -> High Discount | J36: Not Provided
A37: Christmas Fence Garden Decorations Outdoor For Holiday Home | B37: 699 | C37: 1343 | D37: =IF(Excel_jumia_dataset3[[#This Row],[Current Price]]="","Missing",IF(Excel_jumia_dataset3[[#This Row],[Current Price]]<Data_Analysis!$B$21,"Low Price",IF(Excel_jumia_dataset3[[#This Row],[Current Price]]<Data_Analysis!$B$22,"Medium Price","High Price"))) -> Medium Price | E37: =Excel_jumia_dataset3[[#This Row],[Old Price]]-Excel_jumia_dataset3[[#This Row],[Current Price]] -> 644 | F37: 0.48 | G37: =IF(F37<20%,"Low Discount",IF(F37<=40%,"Medium Discount", "High Discount")) -> High Discount | J37: Not Provided
A38: Sewing Machine Needle Threader Stitch Insertion Tool Automatic Quick Sewing | B38: 105 | C38: 200 | D38: =IF(Excel_jumia_dataset3[[#This Row],[Current Price]]="","Missing",IF(Excel_jumia_dataset3[[#This Row],[Current Price]]<Data_Analysis!$B$21,"Low Price",IF(Excel_jumia_dataset3[[#This Row],[Current Price]]<Data_Analysis!$B$22,"Medium Price","High Price"))) -> Low Price | E38: =Excel_jumia_dataset3[[#This Row],[Old Price]]-Excel_jumia_dataset3[[#This Row],[Current Price]] -> 95 | F38: 0.48 | G38: =IF(F38<20%,"Low Discount",IF(F38<=40%,"Medium Discount", "High Discount")) -> High Discount | J38: Not Provided
A39: 100 Pcs Crochet Hook Tool Set Knitting Hook Set With Box | B39: 990 | C39: 1500 | D39: =IF(Excel_jumia_dataset3[[#This Row],[Current Price]]="","Missing",IF(Excel_jumia_dataset3[[#This Row],[Current Price]]<Data_Analysis!$B$21,"Low Price",IF(Excel_jumia_dataset3[[#This Row],[Current Price]]<Data_Analysis!$B$22,"Medium Price","High Price"))) -> Medium Price | E39: =Excel_jumia_dataset3[[#This Row],[Old Price]]-Excel_jumia_dataset3[[#This Row],[Current Price]] -> 510 | F39: 0.34 | G39: =IF(F39<20%,"Low Discount",IF(F39<=40%,"Medium Discount", "High Discount")) -> Medium Discount | H39: 39 | I39: 4.7 | J39: =IF(ISBLANK(I39),"",IF(I39<3,"Poor",IF(I39>=4.5,"Excellent","Average"))) -> Excellent
A40: 12 Litre Insulated Lunch Box Grey | B40: 980 | C40: 1490 | D40: =IF(Excel_jumia_dataset3[[#This Row],[Current Price]]="","Missing",IF(Excel_jumia_dataset3[[#This Row],[Current Price]]<Data_Analysis!$B$21,"Low Price",IF(Excel_jumia_dataset3[[#This Row],[Current Price]]<Data_Analysis!$B$22,"Medium Price","High Price"))) -> Medium Price | E40: =Excel_jumia_dataset3[[#This Row],[Old Price]]-Excel_jumia_dataset3[[#This Row],[Current Price]] -> 510 | F40: 0.34 | G40: =IF(F40<20%,"Low Discount",IF(F40<=40%,"Medium Discount", "High Discount")) -> Medium Discount | H40: 12 | I40: 4.7 | J40: =IF(ISBLANK(I40),"",IF(I40<3,"Poor",IF(I40>=4.5,"Excellent","Average"))) -> Excellent
...

Sheet Data_Analysis
A1: Descriptive Statistics
A2: Description | B2: Value
A3: Total Products | B3: =COUNTA(Excel_jumia_dataset3[Product]) -> 112
A4: Average Current Price of Product | B4: =AVERAGE(Excel_jumia_dataset3[Current Price]) -> 1186.8929
A5: Average Old Price of Products | B5: =AVERAGE(Excel_jumia_dataset3[Old Price]) -> 1811.1071
A6: Average discount percentage | B6: =AVERAGE(Excel_jumia_dataset3[Discount]) -> 0.36776786
A7: Average Product Rating | B7: =AVERAGE(Excel_jumia_dataset3[Rating]) -> 3.8894737
A8: Total Number of Products | B8: =COUNTA(Excel_jumia_dataset3[Product]) -> 112
A9: Total Number of Reviews | B9: =SUM(Excel_jumia_dataset3[Review]) -> 723
A10: Most Expensive Product by Value | B10: =MAX(Excel_jumia_dataset3[Current Price]) -> 3750
A11: Most Expensive Product | B11: =_xlfn.XLOOKUP(MAX(Excel_jumia_dataset3[Current Price]),Excel_jumia_dataset3[Current Price],Excel_jumia_dataset3[Product]) -> 32PCS Portable Cordless Drill Set With Cyclic Battery Drive -26 Variable Speed
A12: Least Expensive Product by Value | B12: =MIN(Excel_jumia_dataset3[Current Price]) -> 38
A13: Least Expensive Products | B13: =_xlfn.XLOOKUP(MIN(Excel_jumia_dataset3[Current Price]),Excel_jumia_dataset3[Current Price],Excel_jumia_dataset3[Product]) -> 3PCS Single Head Knitting Crochet Sweater Needle Set
A15: Trend Analysis (Correlation)
A16: Does a higher discount percentage result in more customer reviews (Discount vs Review) | B16: =CORREL(Excel_jumia_dataset3[Discount],Excel_jumia_dataset3[Review]) -> -0.13682272 | C16: No
A17: Do highly rated products receive more customer reviews (Rating vs Review) | B17: =CORREL(Cleaned_Data!I3:I113,Cleaned_Data!H3:H113) -> 0.057209035 | C17: Slight
A18: Are expensive products rated higher than cheaper products (Current Proce vs Rating) | B18: =CORREL(Excel_jumia_dataset3[Current Price],Excel_jumia_dataset3[Rating]) -> 0.11009021 | C18: Slight
A20: Price Category
A21: Price_Q1 | B21: =_xlfn.QUARTILE.INC(Excel_jumia_dataset3[Current Price],1) -> 493
A22: Price_Q2 | B22: =_xlfn.QUARTILE.INC(Excel_jumia_dataset3[Current Price],3) -> 1669.5
A24: Identify the top 5 products with the highest ratings.
A25: Products | B25: Rating | C25: Reviews | D25: Current Price
A26: Anti-Skid Absorbent Insulation Coaster For Home Office | B26: 5 | C26: 2 | D26: 332 | K26: Excellent
A27: Peacock Throw Pillow Cushion Case For Home Car | B27: 5 | C27: 2 | D27: 195 | K27: Excellent
A28: LASA Aluminum Folding Truck Hand Cart - 68kg Max | B28: 5 | C28: 3 | D28: 2025 | K28: Excellent
A29: DIY File Folder, Office Drawer File Holder, Pen Holder, Desktop Storage Rack | B29: 5 | C29: 1 | D29: 1620 | K29: Excellent
A30: Classic Black Cat Cotton Hemp Pillow Case For Home Car | B30: 5 | C30: 2 | D30: 171 | K30: Excellent
A32: Identify the top 5 producs with the lowest ratings
A33: Products | B33: Rating | C33: Reviews | D33: Current Price
A34: DIY File Folder, Office Drawer File Holder, Pen Holder, Desktop Storage Rack | B34: 2 | C34: 1 | D34: 450
A35: Bedroom Simple Floor Hanging Clothes Rack Single Pole Hat Rack - White | B35: 2.1 | C35: 7 | D35: 1570
A36: Household Pineapple Peeler Peeler | B36: 2.1 | C36: 13 | D36: 2115
A37: Memory Foam Neck Pillow Cover, With Pillow Core - 50*30cm | B37: 2.2 | C37: 6 | D37: 990
A38: Wall-mounted Sticker Punch-free Plug Fixer | B38: 2.2 | C38: 6 | D38: 968
A40: Seller Performance Analysis
A41: Strong Customer Demans vs Reviews | B41: The ones with the highest reviews.
A42: Product | B42: Reviews
A43: 120W Cordless Vacuum Cleaners Handheld Electric Vacuum Cleaner | B43: 69
A44: 137 Pieces Cake Decorating Tool Set Baking Supplies | B44: 55
A45: Electronic Digital Display Vernier Caliper | B45: 49
...

Sheet Product Categories
A2: Count of Product
A3: 112
A5: Rating Category | B5: Count of Product
A6: Average | B6: 22
A7: Excellent | B7: 23
A8: Not Provided | B8: 55
A9: Poor | B9: 12
A10: Grand Total | B10: 112
A13: Discount Category | B13: Count of Product
A14: High Discount | B14: 62
A15: Low Discount | B15: 18
A16: Medium Discount | B16: 32
A17: Grand Total | B17: 112
A19: Price Category | B19: Count of Product
A20: High Price | B20: 88
A21: Low Price | B21: 17
A22: Medium Price | B22: 7
A23: Grand Total | B23: 112
A26: Discount Category | B26: Sum of Review
A27: Medium Discount | B27: 351
A28: High Discount | B28: 334
A29: Low Discount | B29: 38
A30: Grand Total | B30: 723
A33: Price Category | B33: Count of Rating
A34: High Price | B34: 88
A35: Low Price | B35: 17
A36: Medium Price | B36: 7
A37: Grand Total | B37: 112

Sheet Product Performance
A2: Top 10 Products by Rating | B2: Average of Rating
A3: Classic Black Cat Cotton Hemp Pillow Case For Home Car | B3: 5
A4: LASA Aluminum Folding Truck Hand Cart - 68kg Max | B4: 5
A5: Konka Healty Electric Kettle, 24-hour Heat Preservation,1.5L,800W, White | B5: 5
A6: Anti-Skid Absorbent Insulation Coaster For Home Office | B6: 5
A7: Peacock Throw Pillow Cushion Case For Home Car | B7: 5
A8: Bedroom Simple Floor Hanging Clothes Rack Single Pole Hat Rack - White | B8: 5
A9: DIY File Folder, Office Drawer File Holder, Pen Holder, Desktop Storage Rack | B9: 5
A10: LASA FOLDING TABLE SERVING STAND | B10: 4.8
A11: Portable Home Small Air Humidifier 3-Speed Fan - Green | B11: 4.8
A12: 40cm Gold DIY Acrylic Wall Sticker Clock | B12: 4.8
A13: Grand Total | B13: 4.94
A16: Top 10 Products by Number of Reviews | B16: Sum of Review
A17: 120W Cordless Vacuum Cleaners Handheld Electric Vacuum Cleaner | B17: 69
A18: 137 Pieces Cake Decorating Tool Set Baking Supplies | B18: 55
A19: Electronic Digital Display Vernier Caliper | B19: 49
A20: 3D Waterproof EVA Plastic Shower Curtain 1.8*2Mtrs | B20: 44
A21: 100 Pcs Crochet Hook Tool Set Knitting Hook Set With Box | B21: 39
A22: Punch-free Great Load Bearing Bathroom Storage Rack Wall Shelf-White | B22: 36
A23: 53 Pieces/Set Yarn Knitting Crochet Hooks With Bag - Pansies | B23: 32
A24: Portable Mini Cordless Car Vacuum Cleaner - Blue | B24: 24
A25: 52 Pieces Cake Decorating Tool Set Gift Kit Baking Supplies | B25: 20
A26: 53Pcs/Set Yarn Knitting Crochet Hooks With Bag - Fortune Cat | B26: 20
A27: Grand Total | B27: 388
A29: Row Labels | B29: Average of Discount
A30: 6 In 1 Bottle Can Opener Multifunctional Easy Opener | B30: 0.64
A31: LASA FOLDING TABLE SERVING STAND | B31: 0.55
A32: 5-PCS Stainless Steel Cooking Pot Set With Steamed Slices | B32: 0.55
A33: Creative Owl Shape Keychain Black | B33: 0.55
A34: LASA 3 Tier Bamboo Shoe Bench Storage Shelf | B34: 0.54
A35: Mythco 120COB Solar Wall Ligt With Motion Sensor And Remote Control 3 Modes | B35: 0.54
A36: Classic Black Cat Cotton Hemp Pillow Case For Home Car | B36: 0.53
A37: 3PCS Single Head Knitting Crochet Sweater Needle Set | B37: 0.53
A38: Exfoliate And Exfoliate Face Towel - Black | B38: 0.52
A39: Intelligent LED Body Sensor Wireless Lighting Night Light USB | B39: 0.52
A40: Grand Total | B40: 0.54727273

Sheet Trend Analysis

Sheet Dashboard

Sheet Data_Dictionary
A1: Issue | B1: Columns/Rows Affected | C1: Decision | D1: Reason
A2: Duplicates | B2: Column A | C2: Remove Duplicates using the data tools
A3: Discount Amount not provided | B3: Columns B and C | C3: Include a column to for the discount amount | D3: It will be important in our analysis
A4: Discount presented in decimal point | B4: Column E | C4: Convert to rate
A5: Reviews presented as negative | B5: Column F | C5: Remove the -ve sign by replacing with blank
A6: Ratings include out of 5 | B6: Column G | C6: Replace out of 5 with blank (Ctrl H, Replace all)
A7: Rating Category
A8: The price range provided for one of the products | B8: Row 40 | C8: Delete (though I don't thnk we are supposed to delete any data items) | D8: Impossible to determine the price of the item
A10: Identified the top five products with the highest ratings using the sort function in descending order.
A11: Identified the top five products with the lowest ratings using the sort function; in ascending order.
A12: Strong Customer demand dependendent on high reviews
A13: Products the may require better pricing or marketing strategies - based on the least reviews.
A14: The Ratings and Reviews columns that are blank, could be missing data due to data collection errors, but also; a lot of people do not leave reviews/ratings for products
A15: Used Scatter charts to show the relationships in the trend analysis section
